Workbook

Sheet Parameters
A1: OTHER PARAMETERS
A3: Temperature [K] | B3: 310.15
A4: Nh(biomass) [mmol gCDW-1] | B4: 74 | D4: http://www.ncbi.nlm.nih.gov/pubmed/20506321
A5: dfG0(biomass) [kJ gCDW-1] | B5: =-71.075/26.4 -> -2.6922348 | D5: fom Battley 1991; dfGbm = -71.075 (KJ/cmol) | H5: from Lange and Heijnen 2001; cellular density of 26.4 (cmol/gDW)
B7: extracellular [e] | C7: cytosol [c]
A8: pH | B8: 7 | C8: 7.6
A9: Ionic Strength (M) | B9: 0.2 | C9: 0.15
B11: c|>|e
A12: electrical membrane potential [V] | B12: -0.15
A15: DEFAULT BOUNDS FOR VARIABLES
B17: extracellular [e] | D17: cytosol [c]
B18: min | C18: max | D18: min | E18: max
A19: concentration [mM] | B19: 0.0001 | C19: 1 | D19: 0.0001 | E19: 1
A20: gbmo [kJ gCDW-1 h-1] | B20: 0 | C20: 10
A22: PHYSICAL CONSTANTS
A24: Gas constant [kJ mol-1 K-1] | B24: 0.008314
A25: Faraday constant [kC mol-1] | B25: 96.49
A26: Debye-Hückel constant A [M-1/2] | B26: 1.201
A27: Debye-Hückel constant B [M-1/2] | B27: 1.6

Sheet Exchange reactions
A1: Abbrevation | B1: Lower Bound | C1: Upper Bound | D1: Reaction | F1: Comment
A2: EX_12ppd-S | B2: 0 | C2: 0 | D2: 12ppd-S[e] <=>
A3: EX_15dap | B3: 0 | C3: 0 | D3: 15dap[e] <=>
A4: EX_26dap-M | B4: 0 | C4: 0 | D4: 26dap-M[e] <=>
A5: EX_2ddglcn | B5: 0 | C5: 0 | D5: 2ddglcn[e] <=>
A6: EX_3hcinnm | B6: 0 | C6: 0 | D6: 3hcinnm[e] <=>
A7: EX_3hpppn | B7: 0 | C7: 0 | D7: 3hpppn[e] <=>
A8: EX_4abut | B8: 0 | C8: 0 | D8: 4abut[e] <=>
A9: EX_ac | B9: -150 | C9: 150 | D9: ac[e] <=> | F9: measurement and mixed acid fermentation
A10: EX_acac | B10: 0 | C10: 0 | D10: acac[e] <=>
A11: EX_acald | B11: 0 | C11: 0 | D11: acald[e] <=>
A12: EX_acgam | B12: 0 | C12: 0 | D12: acgam[e] <=>
A13: EX_acmana | B13: 0 | C13: 0 | D13: acmana[e] <=>
A14: EX_acnam | B14: 0 | C14: 0 | D14: acnam[e] <=>
A15: EX_ade | B15: 0 | C15: 0 | D15: ade[e] <=>
A16: EX_adn | B16: 0 | C16: 0 | D16: adn[e] <=>
A17: EX_akg | B17: 0 | C17: 0 | D17: akg[e] <=>
A18: EX_ala-D | B18: 0 | C18: 0 | D18: ala-D[e] <=>
A19: EX_ala-L | B19: 0 | C19: 0 | D19: ala-L[e] <=>
A20: EX_alltn | B20: 0 | C20: 0 | D20: alltn[e] <=>
A21: EX_amp | B21: 0 | C21: 0 | D21: amp[e] <=>
... A44: EX_duri | B44: 0 | C44: 0 | D44: duri[e] <=>
A45: EX_etoh | B45: 0 | C45: 150 | D45: etoh[e] <=> | F45: mixed acid fermentation
A46: EX_fe2 | B46: -150 | C46: 150 | D46: fe2[e] <=>
A47: EX_for | B47: 0 | C47: 150 | D47: for[e] <=> | F47: mixed acid fermentation
A48: EX_fru | B48: -150 | C48: 0 | D48: fru[e] <=> | F48: measurement
A49: EX_fuc1p-L | B49: 0 | C49: 0 | D49: fuc1p-L[e] <=>
A50: EX_fuc-L | B50: 0 | C50: 0 | D50: fuc-L[e] <=>
A51: EX_fum | B51: 0 | C51: 150 | D51: fum[e] <=> | F51: mixed acid fermentation
A52: EX_g6p | B52: 0 | C52: 0 | D52: g6p[e] <=>
A53: EX_gal | B53: -150 | C53: 0 | D53: gal[e] <=> | F53: measurement
A54: EX_galct-D | B54: 0 | C54: 0 | D54: galct-D[e] <=>
A55: EX_galctn-D | B55: 0 | C55: 0 | D55: galctn-D[e] <=>
A56: EX_galt | B56: 0 | C56: 0 | D56: galt[e] <=>
A57: EX_galur | B57: 0 | C57: 0 | D57: galur[e] <=>
A58: EX_gam | B58: 0 | C58: 0 | D58: gam[e] <=>
A59: EX_gbbtn | B59: 0 | C59: 0 | D59: gbbtn[e] <=>
A60: EX_glc | B60: -150 | C60: 0 | D60: glc-D[e] <=> | F60: measurement
A61: EX_glcn | B61: -150 | C61: 0 | D61: glcn[e] <=> | F61: measurement
A62: EX_glcr | B62: 0 | C62: 0 | D62: glcr[e] <=>
...

Sheet Reactions
A1: Abbrevation | B1: Lower Bound | C1: Upper Bound | D1: Reaction | F1: OfficialName | G1: Subsystem | H1: ProteinClassDescription | I1: Ref. (listed below)
A2: 2DGLCNRx | B2: 0 | C2: 150 | D2: 2dhglcn[c] + nadh[c] <=> glcn[c] + nad[c] | F2: 2-dehydro-D-gluconate reductase (NADH) | G2: Alternate Carbon Metabolism | I2: 121
A3: 2DGLCNRy | B3: 0 | C3: 150 | D3: 2dhglcn[c] + nadph[c] <=> glcn[c] + nadp[c] | F3: 2-dehydro-D-gluconate reductase (NADPH) | G3: Alternate Carbon Metabolism | H3: EC-1.1.1.215 | I3: 121
A4: 2DGULRx | B4: 0 | C4: 150 | D4: 2dhguln[c] + nadh[c] <=> idon-L[c] + nad[c] | F4: 2-dehydro-L-gulonate reductase (NADH) | G4: Alternate Carbon Metabolism | I4: 121
A5: 2DGULRy | B5: 0 | C5: 150 | D5: 2dhguln[c] + nadph[c] <=> idon-L[c] + nadp[c] | F5: 2-dehydro-L-gulonate reductase (NADPH) | G5: Alternate Carbon Metabolism | I5: 121
A6: 3HCINNMH | B6: 0 | C6: 150 | D6: 3hcinnm[c] + nadh[c] + o2[c] <=> dhcinnm[c] + h2o[c] + nad[c] | F6: 3-hydroxycinnamate hydroxylase | G6: Alternate Carbon Metabolism | I6: 24
A7: 3HPPPNH | B7: 0 | C7: 150 | D7: 3hpppn[c] + nadh[c] + o2[c] <=> dhpppn[c] + h2o[c] + nad[c] | F7: 3-(3-hydroxy-phenyl)propionate hydroxylase | G7: Alternate Carbon Metabolism | I7: 24
A8: 4HTHRS | B8: 0 | C8: 150 | D8: h2o[c] + phthr[c] <=> 4hthr[c] + pi[c] | F8: 4-Hydroxy-L-threonine synthase | G8: Cofactor and Prosthetic Group Biosynthesis
A9: 5DGLCNR | B9: -150 | C9: 150 | D9: 5dglcn[c] + nadph[c] <=> glcn[c] + nadp[c] | F9: 5-dehydro-D-gluconate reductase | G9: Alternate Carbon Metabolism | H9: EC-1.1.1.69 | I9: 5
A10: A5PISO | B10: -150 | C10: 150 | D10: ru5p-D[c] <=> ara5p[c] | F10: arabinose-5-phosphate isomerase | G10: Alternate Carbon Metabolism | H10: EC-5.3.1.13
A11: AACPS1 | B11: 0 | C11: 150 | D11: ACP[c] + atp[c] + ttdca[c] <=> amp[c] + myrsACP[c] + ppi[c] | F11: acyl-[acyl-carrier-protein] synthetase (n-C14:0) | G11: Cell Envelope Biosynthesis | H11: EC-6.2.1.20 | I11: 52
A12: AACPS2 | B12: 0 | C12: 150 | D12: ACP[c] + atp[c] + ttdcea[c] <=> amp[c] + ppi[c] + tdeACP[c] | F12: acyl-[acyl-carrier-protein] synthetase (n-C14:1) | G12: Cell Envelope Biosynthesis | H12: EC-6.2.1.20 | I12: 52
A13: AACPS3 | B13: 0 | C13: 150 | D13: ACP[c] + atp[c] + hdca[c] <=> amp[c] + palmACP[c] + ppi[c] | F13: acyl-[acyl-carrier-protein] synthetase (n-C16:0) | G13: Cell Envelope Biosynthesis | H13: EC-6.2.1.20 | I13: 52
A14: AACPS4 | B14: 0 | C14: 150 | D14: ACP[c] + atp[c] + hdcea[c] <=> amp[c] + hdeACP[c] + ppi[c] | F14: acyl-[acyl-carrier-protein] synthetase (n-C16:1) | G14: Cell Envelope Biosynthesis | H14: EC-6.2.1.20 | I14: 52
A15: AACPS5 | B15: 0 | C15: 150 | D15: ACP[c] + atp[c] + ocdcea[c] <=> amp[c] + octeACP[c] + ppi[c] | F15: acyl-[acyl-carrier-protein] synthetase (n-C18:1) | G15: Cell Envelope Biosynthesis | H15: EC-6.2.1.20 | I15: 52
A16: AADDGT | B16: 0 | C16: 150 | D16: dtdp4aaddg[c] + unagamu[c] <=> dtdp[c] + unagamuf[c] | F16: dTDP-N-4-acetamido-4,6-dideoxy-D-galactose transferase | G16: Cell Envelope Biosynthesis | I16: 90
A17: AB6PGH | B17: 0 | C17: 150 | D17: arbt6p[c] + h2o[c] <=> g6p[c] + hqn[c] | F17: Arbutin 6-phosphate glucohydrolase | G17: Alternate Carbon Metabolism | H17: EC-3.2.1.86 | I17: 88
A18: ABTA | B18: 0 | C18: 150 | D18: 4abut[c] + akg[c] <=> glu-L[c] + sucsal[c] | F18: 4-aminobutyrate transaminase | G18: Arginine and Proline Metabolism | H18: EC-2.6.1.19
A19: ABUTD | B19: 0 | C19: 150 | D19: 4abutn[c] + h2o[c] + nad[c] <=> 4abut[c] + nadh[c] | F19: Aminobutyraldehyde dehydrogenase | G19: Arginine and Proline Metabolism | H19: EC-1.2.1.19
A20: ACACCT | B20: 0 | C20: 150 | D20: acac[c] + accoa[c] <=> aacoa[c] + ac[c] | F20: acetyl-CoA:acetoacetyl-CoA transferase | G20: Alternate Carbon Metabolism | I20: 129
A21: ACACT1r | B21: -150 | C21: 150 | D21: (2) accoa[c] <=> aacoa[c] + coa[c] | F21: acetyl-CoA C-acetyltransferase | G21: Membrane Lipid Metabolism | H21: EC-2.3.1.9
A22: ACALDi | B22: 0 | C22: 150 | D22: acald[c] + coa[c] + nad[c] <=> accoa[c] + nadh[c] | F22: acetaldehyde dehydrogenase (acetylating) | G22: Alternate Carbon Metabolism | H22: EC-1.2.1.10
A23: ACBIPGT | B23: 0 | C23: 150 | D23: adocbip[c] + gtp[c] <=> agdpcbi[c] + ppi[c] | F23: Adenosyl cobinamide phosphate guanyltransferase | G23: Cofactor and Prosthetic Group Biosynthesis | I23: 67
A24: ACCOACr | B24: -150 | C24: 150 | D24: accoa[c] + atp[c] + h2o[c] + co2tot[c] <=> adp[c] + malcoa[c] + pi[c] + h2o[c] | F24: acetyl-CoA carboxylate, reversible reaction | G24: Membrane Lipid Metabolism | H24: EC-6.4.1.2
A25: ACCOAL | B25: 0 | C25: 150 | D25: atp[c] + coa[c] + ppa[c] <=> adp[c] + pi[c] + ppcoa[c] | F25: acetate-CoA ligase (ADP-forming) | G25: Alternate Carbon Metabolism | H25: EC-6.2.1.13 | I25: 106
A26: ACGAMT | B26: 0 | C26: 150 | D26: uacgam[c] + udcpp[c] <=> ump[c] + unaga[c] | F26: UDP-N-acetylglucosamine:undecaprenylphosphate N-acetylglucosamine -1-phosphate transferase | G26: Cell Envelope Biosynthesis | I26: 23
A27: ACGK | B27: 0 | C27: 150 | D27: acglu[c] + atp[c] <=> acg5p[c] + adp[c] | F27: acetylglutamate kinase | G27: Arginine and Proline Metabolism | H27: EC-2.7.2.8
A28: ACGS | B28: 0 | C28: 150 | D28: accoa[c] + glu-L[c] <=> acglu[c] + coa[c] | F28: N-acetylglutamate synthase | G28: Arginine and Proline Metabolism | H28: EC-2.3.1.1
A29: ACHBS | B29: 0 | C29: 150 | D29: 2obut[c] + pyr[c] + h2o[c] <=> 2ahbut[c] + co2tot[c] | F29: 2-aceto-2-hydroxybutanoate synthase | G29: Valine, leucine, and isoleucine metabolism
A30: ACKr | B30: -150 | C30: 150 | D30: ac[c] + atp[c] <=> actp[c] + adp[c] | F30: acetate kinase | G30: Pyruvate metabolism | H30: EC-2.7.2.1
A31: ACLS | B31: 0 | C31: 150 | D31: (2) pyr[c] + h2o[c] <=> alac-S[c] + co2tot[c] | F31: acetolactate synthase | G31: Valine, leucine, and isoleucine metabolism | H31: EC-4.1.3.18
A32: ACMAMUT | B32: 0 | C32: 150 | D32: uacmamu[c] + unaga[c] <=> udp[c] + unagamu[c] | F32: UDP-N-acetyl-D-mannosaminuronic acid transferase | G32: Cell Envelope Biosynthesis | I32: 23
A33: ACNML | B33: 0 | C33: 150 | D33: acnam[c] <=> acmana[c] + pyr[c] | F33: N-Acetylneuraminate lyase | G33: Alternate Carbon Metabolism | H33: EC-4.1.3.3
A34: ACOATA | B34: -150 | C34: 150 | D34: accoa[c] + ACP[c] <=> acACP[c] + coa[c] | F34: Acetyl-CoA ACP transacylase | G34: Membrane Lipid Metabolism | H34: EC-2.3.1.38
A35: ACODA | B35: 0 | C35: 150 | D35: acorn[c] + h2o[c] <=> ac[c] + orn[c] | F35: acetylornithine deacetylase | G35: Arginine and Proline Metabolism | H35: EC-3.5.1.16
A36: ACONMT | B36: 0 | C36: 150 | D36: acon-T[c] + amet[c] <=> aconm[c] + ahcys[c] | F36: Trans-aconitate methyltransferase | G36: Unassigned | I36: 14,15
A37: ACONT | B37: -150 | C37: 150 | D37: cit[c] <=> icit[c] | F37: aconitase | G37: Citrate Cycle (TCA) | H37: EC-4.2.1.3
A38: ACOTA | B38: -150 | C38: 150 | D38: acorn[c] + akg[c] <=> acg5sa[c] + glu-L[c] | F38: acetylornithine transaminase | G38: Arginine and Proline Metabolism | H38: EC-2.6.1.11
A39: ACPS1 | B39: 0 | C39: 150 | D39: apoACP[c] + coa[c] <=> ACP[c] + pap[c] | F39: acyl-carrier protein synthase | G39: Cofactor and Prosthetic Group Biosynthesis | H39: EC-2.7.8.7
A40: ACS | B40: 0 | C40: 150 | D40: ac[c] + atp[c] + coa[c] <=> accoa[c] + amp[c] + ppi[c] | F40: acetyl-CoA synthetase | G40: Pyruvate metabolism | H40: EC-6.2.1.1
...

Sheet Biomass Composition
A1: Abbrevation | B1: Lower Bound | C1: Upper Bound | D1: Reaction | G1: including ATPM
A2: biomass | B2: 0 | C2: 150 | D2: (0.05) 5mthf[c] + (0.00005) accoa[c] + (0.488) ala-L[c] + (0.0010) amp[c] + (0.281) arg-L[c] + (0.229) asn-L[c] + (0.229) asp-L[c] + (22.873) atp[c] + (0.000129) clpnEC[c] + (0.000006) coa[c] + (0.126) ctp[c] + (0.087) cys-L[c] + (0.0247) datp[c] + (0.0254) dctp[c] + (0.0254) dgtp[c] + (0.0247) dttp[c] + (0.00001) fad[c] + (0.25) gln-L[c] + (0.25) glu-L[c] + (0.582) gly[c] + (0.154) glycogen[c] + (0.203) gtp[c] + (22.6878) h2o[c] + (0.09) his-L[c] + (0.276) ile-L[c] + (0.428) leu-L[c] + (0.0084) lpsEC[c] + (0.326) lys-L[c] + (0.146) met-L[c] + (0.00215) nad[c] + (0.00005) nadh[c] + (0.00013) nadp[c] + (0.0004) nadph[c] + (0.001935) peEC[c] + (0.0276) peptidoEC[c] + (0.000464) pgEC[c] + (0.176) phe-L[c] + (0.21) pro-L[c] + (0.000052) psEC[c] + (0.035) ptrc[c] + (0.205) ser-L[c] + (0.0070) spmd[c] + (0.000003) succoa[c] + (0.241) thr-L[c] + (0.054) trp-L[c] + (0.131) tyr-L[c] + (0.0030) udpg[c] + (0.136) utp[c] + (0.402) val-L[c] <=> (22.6878) adp[c] + (22.6898) pi[c] + (0.7302) ppi[c] | G2: (0.05) 5mthf[c] + (0.00005) accoa[c] + (0.488) ala-L[c] + (0.0010) amp[c] + (0.281) arg-L[c] + (0.229) asn-L[c] + (0.229) asp-L[c] + (45.7318) atp[c] + (0.000129) clpnEC[c] + (0.000006) coa[c] + (0.126) ctp[c] + (0.087) cys-L[c] + (0.0247) datp[c] + (0.0254) dctp[c] + (0.0254) dgtp[c] + (0.0247) dttp[c] + (0.00001) fad[c] + (0.25) gln-L[c] + (0.25) glu-L[c] + (0.582) gly[c] + (0.154) glycogen[c] + (0.203) gtp[c] + (45.5608) h2o[c] + (0.09) his-L[c] + (0.276) ile-L[c] + (0.428) leu-L[c] + (0.0084) lpsEC[c] + (0.326) lys-L[c] + (0.146) met-L[c] + (0.00215) nad[c] + (0.00005) nadh[c] + (0.00013) nadp[c] + (0.0004) nadph[c] + (0.001935) peEC[c] + (0.0276) peptidoEC[c] + (0.000464) pgEC[c] + (0.176) phe-L[c] + (0.21) pro-L[c] + (0.000052) psEC[c] + (0.035) ptrc[c] + (0.205) ser-L[c] + (0.0070) spmd[c] + (0.000003) succoa[c] + (0.241) thr-L[c] + (0.054) trp-L[c] + (0.131) tyr-L[c] + (0.0030) udpg[c] + (0.136) utp[c] + (0.402) val-L[c] <=> (45.5608) adp[c] + (45.56035) h[c] + (45.5628) pi[c] + (0.7302) ppi[c] | J2: (0.05) 5mthf[c] + (0.00005) accoa[c] + (0.488) ala-L[c] + (0.0010) amp[c] + (0.281) arg-L[c] + (0.229) asn-L[c] + (0.229) asp-L[c] + (0.1852) atp[c] + (0.000129) clpnEC[c] + (0.000006) coa[c] + (0.126) ctp[c] + (0.087) cys-L[c] + (0.0247) datp[c] + (0.0254) dctp[c] + (0.0254) dgtp[c] + (0.0247) dttp[c] + (0.00001) fad[c] + (0.25) gln-L[c] + (0.25) glu-L[c] + (0.582) gly[c] + (0.154) glycogen[c] + (0.203) gtp[c] + (0.09) his-L[c] + (0.276) ile-L[c] + (0.428) leu-L[c] + (0.0084) lpsEC[c] + (0.326) lys-L[c] + (0.146) met-L[c] + (0.00215) nad[c] + (0.00005) nadh[c] + (0.00013) nadp[c] + (0.0004) nadph[c] + (0.001935) peEC[c] + (0.0276) peptidoEC[c] + (0.000464) pgEC[c] + (0.176) phe-L[c] + (0.21) pro-L[c] + (0.000052) psEC[c] + (0.035) ptrc[c] + (0.205) ser-L[c] + (0.0070) spmd[c] + (0.000003) succoa[c] + (0.241) thr-L[c] + (0.054) trp-L[c] + (0.131) tyr-L[c] + (0.0030) udpg[c] + (0.136) utp[c] + (0.402) val-L[c] <=> (0.002) pi[c] + (0.7302) ppi[c]

Sheet Transmembrane reactions
A1: Abbrevation | B1: Lower Bound | C1: Upper Bound | D1: Reaction | E1: Intracellular part | F1: Transmembrane transport | G1: Transport map | I1: OfficialName | J1: reed Formula | K1: Subsystem | L1: EC Number | M1: ref
A2: 12PPDt | B2: -150 | C2: 150 | D2: 12ppd-S[e] <=> 12ppd-S[c] | F2: 12ppd-S{0}[e] <=> 12ppd-S{0}[c] | G2: c|>|e | I2: S-Propane-1,2-diol facilitated transport | J2: 12ppd-S[e] <=> 12ppd-S[c] | K2: Transport, Extracellular | M2: 125
A3: ABUTt2 | B3: 0 | C3: 150 | D3: 4abut[e] <=> 4abut[c] | F3: 4abut{0}[e] <=> 4abut{0}[c] | G3: c|>|e | I3: 4-aminobutyrate transport in via proton symport | J3: 4abut[e] + h[e] <=> 4abut[c] + h[c] | K3: Transport, Extracellular
A4: ACACt2 | B4: -150 | C4: 150 | D4: acac[e] <=> acac[c] | F4: acac{-1}[e] + h{1}[e] <=> acac{-1}[c] + h{1}[c] | G4: c|>|e | I4: acetoacetate transport via proton symport | J4: acac[e] + h[e] <=> acac[c] + h[c] | K4: Putative Transporters
A5: ACALDt | B5: -150 | C5: 150 | D5: acald[e] <=> acald[c] | F5: acald{0}[e] <=> acald{0}[c] | G5: c|>|e | I5: acetaldehyde reversible transport | J5: acald[e] <=> acald[c] | K5: Transport, Extracellular
A6: ACGApts | B6: -150 | C6: 150 | D6: acgam[e] + pep[c] <=> acgam6p[c] + pyr[c] | E6: acgam[c] + pep[c] <=> acgam6p[c] + pyr[c] | F6: acgam{0}[e] <=> acgam{0}[c] | G6: c|>|e | I6: N-Acetyl-D-glucosamine transport via PEP:Pyr PTS | J6: acgam[e] + pep[c] <=> acgam6p[c] + pyr[c] | K6: Transport, Extracellular | M6: 132
A7: ACMANApts | B7: -150 | C7: 150 | D7: acmana[e] + pep[c] <=> acmanap[c] + pyr[c] | E7: acmana[c] + pep[c] <=> acmanap[c] + pyr[c] | F7: acmana{0}[e] <=> acmana{0}[c] | G7: c|>|e | I7: N-acetyl-D-mannosamine transport via PTS | J7: acmana[e] + pep[c] <=> acmanap[c] + pyr[c] | K7: Transport, Extracellular | M7: 84
A8: ACNAMt2 | B8: -150 | C8: 150 | D8: acnam[e] <=> acnam[c] | F8: acnam{-1}[e] + h{1}[e] <=> acnam{-1}[c] + h{1}[c] | G8: c|>|e | I8: N-acetylneuraminate proton symport | J8: acnam[e] + h[e] <=> acnam[c] + h[c] | K8: Transport, Extracellular
A9: ACt2r | B9: -150 | C9: 150 | D9: ac[e] <=> ac[c] | F9: ac{-1}[e] + h{1}[e] <=> ac{-1}[c] + h{1}[c] | G9: c|>|e | I9: acetate reversible transport via proton symport | J9: ac[e] + h[e] <=> ac[c] + h[c] | K9: Transport, Extracellular
A10: ADEt2r | B10: -150 | C10: 150 | D10: ade[e] <=> ade[c] | F10: ade{0}[e] <=> ade{0}[c] | G10: c|>|e | I10: adenine transport via proton symport (reversible) | J10: ade[e] + h[e] <=> ade[c] + h[c] | K10: Transport, Extracellular
A11: ADNt2 | B11: -150 | C11: 150 | D11: adn[e] <=> adn[c] | F11: adn{0}[e] <=> adn{0}[c] | G11: c|>|e | I11: adenosine transport in via proton symport | J11: adn[e] + h[e] <=> adn[c] + h[c] | K11: Transport, Extracellular
A12: AKGt2r | B12: -150 | C12: 150 | D12: akg[e] <=> akg[c] | F12: akg{-2}[e] + (2) h{1}[e] <=> akg{-2}[c] + (2) h{1}[c] | G12: c|>|e | I12: 2-oxoglutarate reversible transport via symport | J12: akg[e] + h[e] <=> akg[c] + h[c] | K12: Transport, Extracellular
A13: ALAabc | B13: 0 | C13: 150 | D13: ala-L[e] + (2) atp[c] + (2) h2o[c] <=> (2) adp[c] + ala-L[c] + (2) pi[c] | E13: (2) atp[c] + (2) h2o[c] <=> (2) adp[c] + (2) pi[c] | F13: ala-L{0}[e] <=> ala-L{0}[c] | G13: c|>|e | I13: L-alanine transport via ABC system | J13: ala-L[e] + atp[c] + h2o[c] <=> adp[c] + ala-L[c] + h[c] + pi[c] | K13: Transport, Extracellular | M13: 93
A14: ALARi | B14: -150 | C14: 150 | D14: ala-L[e] <=> ala-L[c] | F14: ala-L{0}[e] <=> ala-L{0}[c] | G14: c|>|e | I14: alanine racemase (irreversible) | J14: ala-L[c] <=> ala-D[c] | K14: Alanine and aspartate metabolism | L14: EC-5.1.1.1
A15: ALLTNt2r | B15: -150 | C15: 150 | D15: alltn[e] <=> alltn[c] | F15: alltn{0}[e] <=> alltn{0}[c] | G15: c|>|e | I15: allantoin transport in via proton symport | J15: alltn[e] + h[e] <=> alltn[c] + h[c] | K15: Putative Transporters
A16: ARBabc | B16: 0 | C16: 150 | D16: arab-L[e] + (2) atp[c] + (2) h2o[c] <=> (2) adp[c] + arab-L[c] + (2) pi[c] | E16: (2) atp[c] + (2) h2o[c] <=> (2) adp[c] + (2) pi[c] | F16: arab-L{0}[e] <=> arab-L{0}[c] | G16: c|>|e | I16: L-arabinose transport via ABC system | J16: arab-L[e] + atp[c] + h2o[c] <=> adp[c] + arab-L[c] + h[c] + pi[c] | K16: Transport, Extracellular
A17: ARBt2r | B17: -150 | C17: 150 | D17: arab-L[e] <=> arab-L[c] | F17: arab-L{0}[e] <=> arab-L{0}[c] | G17: c|>|e | I17: L-arabinose transport via proton symport | J17: arab-L[e] + h[e] <=> arab-L[c] + h[c] | K17: Transport, Extracellular
A18: ARGabc | B18: 0 | C18: 150 | D18: arg-L[e] + (2) atp[c] + (2) h2o[c] <=> (2) adp[c] + arg-L[c] + (2) pi[c] | E18: (2) atp[c] + (2) h2o[c] <=> (2) adp[c] + (2) pi[c] | F18: arg-L{1}[e] <=> arg-L{1}[c] | G18: c|>|e | I18: L-arginine transport via ABC system | J18: arg-L[e] + atp[c] + h2o[c] <=> adp[c] + arg-L[c] + h[c] + pi[c] | K18: Transport, Extracellular
A19: ARGORNt7 | B19: -150 | C19: 150 | D19: arg-L[e] + orn[c] <=> arg-L[c] + orn[e] | F19: arg-L{1}[e] + orn{1}[c] <=> arg-L{1}[c] + orn{1}[e] | G19: c|>|e | I19: arginine/ornithine antiporter | J19: arg-L[e] + orn[c] <=> arg-L[c] + orn[e] | K19: Putative Transporters
A20: ASNabc | B20: 0 | C20: 150 | D20: asn-L[e] + (2) atp[c] + (2) h2o[c] <=> (2) adp[c] + asn-L[c] + (2) pi[c] | E20: (2) atp[c] + (2) h2o[c] <=> (2) adp[c] + (2) pi[c] | F20: asn-L{0}[e] <=> asn-L{0}[c] | G20: c|>|e | I20: L-asparagine transport via ABC system | J20: asn-L[e] + atp[c] + h2o[c] <=> adp[c] + asn-L[c] + h[c] + pi[c] | K20: Transport, Extracellular
A21: ASNt2r | B21: -150 | C21: 150 | D21: asn-L[e] <=> asn-L[c] | F21: asn-L{0}[e] <=> asn-L{0}[c] | G21: c|>|e | I21: L-asparagine reversible transport via proton symport | J21: asn-L[e] + h[e] <=> asn-L[c] + h[c] | K21: Transport, Extracellular
A22: ASPabc | B22: 0 | C22: 150 | D22: asp-L[e] + (2) atp[c] + (2) h2o[c] <=> (2) adp[c] + asp-L[c] + (2) pi[c] | E22: (2) atp[c] + (2) h2o[c] <=> (2) adp[c] + (2) pi[c] | F22: asp-L{-1}[e] <=> asp-L{-1}[c] | G22: c|>|e | I22: L-aspartate transport via ABC system | J22: asp-L[e] + atp[c] + h2o[c] <=> adp[c] + asp-L[c] + h[c] + pi[c] | K22: Transport, Extracellular
A23: ASPt2 | B23: 0 | C23: 150 | D23: asp-L[e] <=> asp-L[c] | F23: asp-L{-1}[e] + h{1}[e] <=> asp-L{-1}[c] + h{1}[c] | G23: c|>|e | I23: L-aspartate transport in via proton symport | J23: asp-L[e] + h[e] <=> asp-L[c] + h[c] | K23: Transport, Extracellular
A24: ATPS4r | B24: -150 | C24: 150 | D24: adp[c] + pi[c] <=> atp[c] + h2o[c] | E24: adp[c] + pi[c] <=> atp[c] + h2o[c] | F24: (4) h{1}[e] <=> (4) h{1}[c] | G24: c|>|e | I24: ATP synthase (four protons for one ATP) | J24: adp[c] + (4) h[e] + pi[c] <=> atp[c] + (3) h[c] + h2o[c] | K24: Oxidative phosphorylation | L24: EC-3.6.3.14
A25: BUTt2r | B25: -150 | C25: 150 | D25: but[e] <=> but[c] | F25: but{-1}[e] + h{1}[e] <=> but{-1}[c] + h{1}[c] | G25: c|>|e | I25: Butyrate transport via proton symport, reversible | J25: but[e] + h[e] <=> but[c] + h[c] | K25: Putative Transporters
A26: CADVt | B26: 0 | C26: 150 | D26: 15dap[c] + lys-L[e] <=> 15dap[e] + lys-L[c] | F26: 15dap{2}[c] + h{1}[e] + lys-L{1}[e] <=> 15dap{2}[e] + h{1}[c] + lys-L{1}[c] | G26: c|>|e | I26: Lysine/Cadaverine antiporter | J26: 15dap[c] + h[e] + lys-L[e] <=> 15dap[e] + h[c] + lys-L[c] | K26: Transport, Extracellular
A27: CBL1abc | B27: -150 | C27: 150 | D27: (2) atp[c] + cbl1[e] + (2) h2o[c] <=> (2) adp[c] + cbl1[c] + (2) pi[c] | E27: (2) atp[c] + (2) h2o[c] <=> (2) adp[c] + (2) pi[c] | F27: cbl1{-1}[e] <=> cbl1{-1}[c] | G27: c|>|e | I27: Cob(1)alamin transport via ABC system | J27: atp[c] + cbl1[e] + h2o[c] <=> adp[c] + cbl1[c] + h[c] + pi[c] | K27: Transport, Extracellular | M27: 13141
A28: Cex | B28: -150 | C28: 150 | F28: charge{1}[c] <=> charge{1}[e] | G28: c|>|e | K28: Transport, Extracellular
A29: CHLabc | B29: 0 | C29: 150 | D29: (2) atp[c] + chol[e] + (2) h2o[c] <=> (2) adp[c] + chol[c] + (2) pi[c] | E29: (2) atp[c] + (2) h2o[c] <=> (2) adp[c] + (2) pi[c] | F29: chol{1}[e] <=> chol{1}[c] | G29: c|>|e | I29: choline transport via ABC system | J29: atp[c] + chol[e] + h2o[c] <=> adp[c] + chol[c] + h[c] + pi[c] | K29: Putative Transporters
A30: CHLt2r | B30: -150 | C30: 150 | D30: chol[e] <=> chol[c] | F30: chol{1}[e] + h{1}[c] <=> chol{1}[c] + h{1}[e] | G30: c|>|e | I30: choline transport via proton symport, reversible | J30: chol[e] + h[e] <=> chol[c] + h[c] | K30: Transport, Extracellular | M30: 64
A31: CITt7 | B31: 0 | C31: 150 | D31: cit[e] + succ[c] <=> cit[c] + succ[e] | F31: cit{-3}[e] + h{1}[e] + succ{-2}[c] <=> cit{-3}[c] + h{1}[c] + succ{-2}[e] | G31: c|>|e | I31: Citrate transport via succinate antiport | J31: cit[e] + succ[c] <=> cit[c] + succ[e] | K31: Transport, Extracellular | M31: 87
A32: CO2t | B32: -150 | C32: 150 | D32: co2tot[e] <=> co2tot[c] | F32: co2tot{-1}[e] + h{1}[e] <=> co2tot{-1}[c] + h{1}[c] | G32: c|>|e | I32: CO2 transporter via diffusion | J32: co2tot[e] <=> co2tot[c] | K32: Transport, Extracellular
A33: CRNt7 | B33: -150 | C33: 150 | D33: crn[e] + gbbtn[c] <=> crn[c] + gbbtn[e] | F33: crn{0}[e] + gbbtn{0}[c] <=> crn{0}[c] + gbbtn{0}[e] | G33: c|>|e | I33: Carnitine/butyrobetaine antiporter | J33: crn[e] + gbbtn[c] <=> crn[c] + gbbtn[e] | K33: Transport, Extracellular | M33: 54
A34: CSNt2 | B34: 0 | C34: 150 | D34: csn[e] <=> csn[c] | F34: csn{0}[e] <=> csn{0}[c] | G34: c|>|e | I34: cytosine transport in via proton symport | J34: csn[e] + h[e] <=> csn[c] + h[c] | K34: Transport, Extracellular
A35: CSNt2_add | B35: -150 | C35: 150 | D35: csn[e] <=> csn[c] | F35: csn{-1}[e] + h{1}[e] <=> csn{-1}[c] + h{1}[c] | G35: c|>|e | K35: Transport, Extracellular
A36: CYNTt2 | B36: 0 | C36: 150 | D36: cynt[e] <=> cynt[c] | F36: cynt{-1}[e] + h{1}[e] <=> cynt{-1}[c] + h{1}[c] | G36: c|>|e | I36: Cyanate transport via proton symport | J36: cynt[e] + h[e] <=> cynt[c] + h[c] | K36: Putative Transporters | M36: 105142
A37: CYSabc | B37: -150 | C37: 150 | D37: (2) atp[c] + cys-L[e] + (2) h2o[c] <=> (2) adp[c] + cys-L[c] + (2) pi[c] | E37: (2) atp[c] + (2) h2o[c] <=> (2) adp[c] + (2) pi[c] | F37: cys-L{0}[e] <=> cys-L{0}[c] | G37: c|>|e | I37: L-cysteine transport via ABC system | J37: atp[c] + cys-L[e] + h2o[c] <=> adp[c] + cys-L[c] + h[c] + pi[c] | K37: Transport, Extracellular
A38: CYTBD | B38: 0 | C38: 150 | D38: (0.5) o2[c] + q8h2[c] <=> h2o[c] + q8[c] | E38: (0.5) o2[c] + q8h2[c] <=> h2o[c] + q8[c] | F38: (2) h{1}[c] <=> (2) h{1}[e] | G38: c|>|e | H38: bd (micro aero.) | I38: cytochrome oxidase bd (ubiquinol-8: 2 protons) | J38: (2) h[c] + (0.5) o2[c] + q8h2[c] <=> (2) h[e] + h2o[c] + q8[c] | K38: Oxidative phosphorylation
A39: CYTBO3 | B39: 0 | C39: 150 | D39: (0.5) o2[c] + q8h2[c] <=> h2o[c] + q8[c] | E39: (0.5) o2[c] + q8h2[c] <=> h2o[c] + q8[c] | F39: (4) h{1}[c] <=> (4) h{1}[e] | G39: c|>|e | H39: bo3 (aerob) | I39: cytochrome oxidase bo3 (ubiquinol-8: 2.5 protons) | J39: (2.5) h[c] + (0.5) o2[c] + q8h2[c] <=> (2.5) h[e] + h2o[c] + q8[c] | K39: Oxidative phosphorylation
A40: CYTDt2 | B40: -150 | C40: 150 | D40: cytd[e] <=> cytd[c] | F40: cytd{0}[e] <=> cytd{0}[c] | G40: c|>|e | I40: cytidine transport in via proton symport | J40: cytd[e] + h[e] <=> cytd[c] + h[c] | K40: Transport, Extracellular | M40: 75
...

Sheet Metabolites
B1: Concentration Limits
B2: extracellular space [e] | D2: intracellular space [c]
A3: Abbreviation | B3: lb | C3: ub | D3: lb | E3: ub | H3: CID | I3: charge | J3: nH | L3: metabolit name | M3: molecular formular
A4: 10fthf | D4: =Parameters!$D$19 -> 0.0001 | E4: =Parameters!$E$19 -> 1 | H4: C00234 | I4: -2 | J4: 21 | L4: 10-Formyltetrahydrofolate | M4: C20H22N7O7
A5: 12dgrEC | D5: =Parameters!$D$19 -> 0.0001 | E5: =Parameters!$E$19 -> 1 | H5: C95022 | I5: 0 | J5: 3448 | L5: 1,2-Diacylglycerol (E.coli) ** | M5: C1836H3448O250
A6: 12ppd-S | B6: =Parameters!$B$19 -> 0.0001 | C6: =Parameters!$C$19 -> 1 | D6: =Parameters!$D$19 -> 0.0001 | E6: =Parameters!$E$19 -> 1 | H6: C02917 | I6: 0 | J6: 8 | L6: (S)-Propane-1,2-diol | M6: C3H8O2
A7: 13dpg | D7: =Parameters!$D$19 -> 0.0001 | E7: =Parameters!$E$19 -> 1 | H7: C00236 | I7: -4 | J7: 4 | L7: 3-Phospho-D-glyceroyl phosphate | M7: C3H4O10P2
A8: 15dap | B8: =Parameters!$B$19 -> 0.0001 | C8: =Parameters!$C$19 -> 1 | D8: =Parameters!$D$19 -> 0.0001 | E8: =Parameters!$E$19 -> 1 | H8: C01672 | I8: 2 | J8: 16 | L8: 1,5-Diaminopentane | M8: C5H16N2
A9: 1pyr5c | D9: =Parameters!$D$19 -> 0.0001 | E9: =Parameters!$E$19 -> 1 | H9: C03912 | I9: -1 | J9: 6 | L9: 1-Pyrroline-5-carboxylate | M9: C5H6NO2
A10: 23ddhb | D10: =Parameters!$D$19 -> 0.0001 | E10: =Parameters!$E$19 -> 1 | H10: C04171 | I10: -1 | J10: 7 | L10: 2,3-Dihydro-2,3-dihydroxybenzoate | M10: C7H7O4
A11: 23dhb | D11: =Parameters!$D$19 -> 0.0001 | E11: =Parameters!$E$19 -> 1 | H11: C00196 | I11: -1 | J11: 5 | L11: 2,3-Dihydroxybenzoate | M11: C7H5O4
A12: 23dhba | D12: =Parameters!$D$19 -> 0.0001 | E12: =Parameters!$E$19 -> 1 | H12: C04030 | I12: -1 | J12: 17 | L12: (2,3-Dihydroxybenzoyl)adenylate | M12: C17H16N5O10P
A13: 23dhdp | D13: =Parameters!$D$19 -> 0.0001 | E13: =Parameters!$E$19 -> 1 | H13: C03340 | I13: -2 | J13: 5 | L13: 2,3-Dihydrodipicolinate | M13: C7H5NO4
A14: 23dhmb | D14: =Parameters!$D$19 -> 0.0001 | E14: =Parameters!$E$19 -> 1 | H14: C04272 | I14: -1 | J14: 9 | L14: (R)-2,3-Dihydroxy-3-methylbutanoate | M14: C5H9O4
A15: 23dhmp | D15: =Parameters!$D$19 -> 0.0001 | E15: =Parameters!$E$19 -> 1 | H15: C06007 | I15: -1 | J15: 11 | L15: (R)-2,3-Dihydroxy-3-methylpentanoate | M15: C6H11O4
A16: 23doguln | D16: =Parameters!$D$19 -> 0.0001 | E16: =Parameters!$E$19 -> 1 | H16: C04575 | I16: -1 | J16: 7 | L16: 2,3-Dioxo-L-gulonate | M16: C6H7O7
A17: 25aics | D17: =Parameters!$D$19 -> 0.0001 | E17: =Parameters!$E$19 -> 1 | H17: C04823 | I17: -4 | J17: 15 | L17: (S)-2-[5-Amino-1-(5-phospho-D-ribosyl)imidazole-4-carboxamido]succinate | M17: C13H15N4O12P
A18: 25dkglcn | D18: =Parameters!$D$19 -> 0.0001 | E18: =Parameters!$E$19 -> 1 | H18: C02780 | I18: -1 | J18: 7 | L18: 2,5-diketo-D-gluconate | M18: C6H7O7
A19: 25drapp | D19: =Parameters!$D$19 -> 0.0001 | E19: =Parameters!$E$19 -> 1 | H19: C01304 | I19: -2 | J19: 14 | L19: 2,5-Diamino-6-(ribosylamino)-4-(3H)-pyrimidinone 5'-phosphate | M19: C9H14N5O8P
A20: 26dap-LL | D20: =Parameters!$D$19 -> 0.0001 | E20: =Parameters!$E$19 -> 1 | H20: C00666 | I20: 0 | J20: 14 | L20: LL-2,6-Diaminoheptanedioate | M20: C7H14N2O4
A21: 26dap-M | B21: =Parameters!$B$19 -> 0.0001 | C21: =Parameters!$C$19 -> 1 | D21: =Parameters!$D$19 -> 0.0001 | E21: =Parameters!$E$19 -> 1 | H21: C00680 | I21: 0 | J21: 14 | L21: meso-2,6-Diaminoheptanedioate | M21: C7H14N2O4
A22: 2ahbut | D22: =Parameters!$D$19 -> 0.0001 | E22: =Parameters!$E$19 -> 1 | H22: C06006 | I22: -1 | J22: 9 | L22: (S)-2-Aceto-2-hydroxybutanoate | M22: C6H9O4
A23: 2aobut | D23: =Parameters!$D$19 -> 0.0001 | E23: =Parameters!$E$19 -> 1 | H23: C03508 | I23: 0 | J23: 7 | L23: L-2-Amino-3-oxobutanoate | M23: C4H7NO3
A24: 2cpr5p | D24: =Parameters!$D$19 -> 0.0001 | E24: =Parameters!$E$19 -> 1 | H24: C01302 | I24: -3 | J24: 13 | L24: 1-(2-Carboxyphenylamino)-1-deoxy-D-ribulose 5-phosphate | M24: C12H13NO9P
A25: 2dda7p | D25: =Parameters!$D$19 -> 0.0001 | E25: =Parameters!$E$19 -> 1 | H25: C04691 | I25: -3 | J25: 10 | L25: 2-Dehydro-3-deoxy-D-arabino-heptonate 7-phosphate | M25: C7H10O10P
A26: 2ddg6p | D26: =Parameters!$D$19 -> 0.0001 | E26: =Parameters!$E$19 -> 1 | H26: C04442 | I26: -3 | J26: 8 | L26: 2-Dehydro-3-deoxy-D-gluconate 6-phosphate | M26: C6H8O9P
A27: 2ddglcn | B27: =Parameters!$B$19 -> 0.0001 | C27: =Parameters!$C$19 -> 1 | D27: =Parameters!$D$19 -> 0.0001 | E27: =Parameters!$E$19 -> 1 | H27: C00204 | I27: -1 | J27: 9 | L27: 2-Dehydro-3-deoxy-D-gluconate | M27: C6H9O6
A28: 2dh3dgal | D28: =Parameters!$D$19 -> 0.0001 | E28: =Parameters!$E$19 -> 1 | H28: C01216 | I28: -1 | J28: 9 | L28: 2-Dehydro-3-deoxy-D-galactonate | M28: C6H9O6
A29: 2dh3dgal6p | D29: =Parameters!$D$19 -> 0.0001 | E29: =Parameters!$E$19 -> 1 | H29: C01286 | I29: -3 | J29: 8 | L29: 2-Dehydro-3-deoxy-D-galactonate 6-phosphate | M29: C6H8O9P
A30: 2dhglcn | D30: =Parameters!$D$19 -> 0.0001 | E30: =Parameters!$E$19 -> 1 | H30: C95000 | I30: -1 | J30: 8 | L30: 2-Dehydro-D-gluconate | M30: C6H9O7
A31: 2dhguln | D31: =Parameters!$D$19 -> 0.0001 | E31: =Parameters!$E$19 -> 1 | H31: C06473 | I31: -1 | J31: 9 | L31: 2-Dehydro-L-gulonate | M31: C6H9O7
A32: 2dhp | D32: =Parameters!$D$19 -> 0.0001 | E32: =Parameters!$E$19 -> 1 | H32: C00966 | I32: -1 | J32: 9 | L32: 2-Dehydropantoate | M32: C6H9O4
A33: 2dmmq8 | D33: =Parameters!$D$19 -> 0.0001 | E33: =Parameters!$E$19 -> 1 | H33: C99995 | I33: 0 | J33: 70 | L33: 2-Demethylmenaquinone 8 | M33: C50H70O2
A34: 2dmmql8 | D34: =Parameters!$D$19 -> 0.0001 | E34: =Parameters!$E$19 -> 1 | H34: C99759 | I34: 0 | J34: 72 | L34: 2-Demethylmenaquinol 8 | M34: C50H72O2
A35: 2dr1p | D35: =Parameters!$D$19 -> 0.0001 | E35: =Parameters!$E$19 -> 1 | H35: C00672 | I35: -2 | J35: 9 | L35: 2-Deoxy-D-ribose 1-phosphate | M35: C5H9O7P
A36: 2dr5p | D36: =Parameters!$D$19 -> 0.0001 | E36: =Parameters!$E$19 -> 1 | H36: C00673 | I36: -2 | J36: 9 | L36: 2-Deoxy-D-ribose 5-phosphate | M36: C5H9O7P
A37: 2h3oppan | D37: =Parameters!$D$19 -> 0.0001 | E37: =Parameters!$E$19 -> 1 | H37: C01146 | I37: -1 | J37: 3 | L37: 2-Hydroxy-3-oxopropanoate | M37: C3H3O4
A38: 2ippm | D38: =Parameters!$D$19 -> 0.0001 | E38: =Parameters!$E$19 -> 1 | H38: C02631 | I38: -2 | J38: 8 | L38: 2-Isopropylmaleate | M38: C7H8O4
A39: 2kmb | D39: =Parameters!$D$19 -> 0.0001 | E39: =Parameters!$E$19 -> 1 | H39: C01180 | I39: -1 | J39: 6 | L39: 2-keto-4-methylthiobutyrate | M39: C5H7O3S
... A63: 3dhsk | D63: =Parameters!$D$19 -> 0.0001 | E63: =Parameters!$E$19 -> 1 | H63: C02637 | I63: -1 | J63: 7 | L63: 3-Dehydroshikimate | M63: C7H7O5
...

Sheet references
A1: REFERENCES
A2: Articles
A3: 1 | B3: Adam P, Hecht S, Eisenreich W, Kaiser J, Grawert T, Arigoni D, Bacher A, Rohdich F: Biosynthesis of terpenes: Studies on 1-hydroxy-2-methyl-2-(E)-butenyl 4-diphosphate reductase. Proc Natl Acad Sci U S A 2002, 99:12103-12113
A4: 2 | B4: Andrianopoulos K, Wang L, Reeves PR.: Identification of the fucose synthetase gene in the colanic acid gene cluster of Escherichia coli K-12.. J Bacteriol 1998, 180:998-1001
A5: 3 | B5: Ashiuchi M, Misono H.: Biochemical evidence that Escherichia coli hyi (orf b0508, gip) gene encodes hydroxypyruvate isomerase.. Biochim Biophys Acta 1999, 1435:153-159
A6: 4 | B6: Azizan A, Sherin D, DiRusso CC, Black PN: Energetics underlying the process of long-chain fatty acid transport. Arch Biochem Biophys 1999, 365:299-306
A7: 5 | B7: Bausch C, Peekhaus N, Utz C, Blais T, Murray E, Lowary T, Conway T: Sequence analysis of the GntII (subsidiary) system for gluconate metabolism reveals a novel pathway for L-idonic acid catabolism in Escherichia coli. J Bacteriol 1998, 180:3704-3710
A8: 6 | B8: Begley TP, Downs DM, Ealick SE, McLafferty FW, Van Loon AP, Taylor S, Campobasso N, Chiu HJ, Kinsland C, Reddick JJ, Xi J: Thiamin biosynthesis in prokaryotes. Arch Microbiol 1999, 171:293-300
A9: 7 | B9: Bhatnagar SK, Bullions LC, Bessman MJ: Characterization of the mutT nucleoside triphosphatase of Escherichia coli.. J Biol Chem 1991, 266:9050-9054
A10: 8 | B10: Blank L, Green J, Guest JR: AcnC of Escherichia coli is a 2-methylcitrate dehydratase (PrpD) that can use citrate and isocitrate as substrates. Microbiology 2002, 148:133-146
A11: 9 | B11: Bollinger JM Jr, Kwon DS, Huisman GW, Kolter R, Walsh CT.: Glutathionylspermidine metabolism in Escherichia coli. Purification, cloning, overproduction, and characterization of a bifunctional glutathionylspermidine synthetase/amidase.. J Biol Chem 1995, 270:14031-14041
A12: 10 | B12: Boos W, Shuman H.: Maltose/maltodextrin system of Escherichia coli: transport, metabolism, and regulation.. Microbiol Mol Biol Rev 1998, 62:204-229
A13: 11 | B13: Brock M, Maerker C, Schutz A, Volker U, Buckel W.: Oxidation of propionate to pyruvate in Escherichia coli. Involvement of methylcitrate dehydratase and aconitase.. Eur J Biochem 2002, 269:6184-6194
A14: 12 | B14: Bugg TD.: Overproduction, purification and properties of 2,3-dihydroxyphenylpropionate 1,2-dioxygenase from Escherichia coli.. Biochim Biophys Acta 1993, 1202:258-264
... A128: 126 | B128: Zientz E, Six S, Unden G.: Identification of a third secondary carrier (DcuC) for anaerobic C4-dicarboxylate transport in Escherichia coli: roles of the three Dcu carriers in uptake and exchange.. J Bacteriol 1996, 178:7241-7247
A130: Books
A131: 127 | B131: Bock,A. and G. Sawers: Fermentation. In Escherichia coli and Salmonella Cellular and Molecular Biology. ASM Press; 1996
A132: 128 | B132: C.R.H. Raetz: Bacterial Lipopolysaccharides: a Remarkable Family of Bioactive Macroamphiphiles. In Escherichia coli and Salmonella Cellular and Molecular Biology. ASM Press; 1996
A133: 129 | B133: Clark, DP and JE Cronan Jr: C2 Compounds and Fatty Acids as Carbon Sources. In Escherichia coli and Salmonella Cellular and Molecular Biology. ASM Press; 1996
A134: 130 | B134: Cronan, J.E. and C.O. Rock: Biosynthesis of Membrane Lipids. In Escherichia coli and Salmonella Cellular and Molecular Biology. ASM Press; 1996
A135: 131 | B135: E. McFall and E.B. Newman: Amino Acids as Carbon Sources. In Escherichia coli and Salmonella Cellular and Molecular Biology. ASM Press; 1996
A136: 132 | B136: E.C.C.Lin: Dissimilatory Pathways for Sugars, Polyols, and Carboxylates. In Escherichia coli and Salmonella Cellular and Molecular Biology. ASM Press; 1996
A137: 133 | B137: G.A. O'Toole, M.R. Rondon, J.R. Trzebiatowski, S.J. Suh and J.C. Escalante-Semerena: Biosynthesis and Utilization of Adenosyl-Cobalamin (Coenzyme B12). In Escherichia coli and Salmonella Cellular and Molecular Biology. ASM Press; 1996
A138: 134 | B138: M. E. Winkler: Biosynthesis of Histidine. In Escherichia coli and Salmonella Cellular and Molecular Biology. ASM Press; 1996
A139: 135 | B139: Maloney PC and TH Wilson: Ion Coupled Transport and Transporters. In Escherichia coli and Salmonella Cellular and Molecular Biology. ASM Press; 1996
A140: 136 | B140: Neidhardt, F.C., Ingraham, J.L., and Schaechter, M.: . In Physiology of the Bacterial Cell A Molecular Approach. Sinauer Associates; 1990
A141: 137 | B141: Penfound T and JW Foster: Biosynthesis and Recycling of NAD. In Escherichia coli and Salmonella Cellular and Molecular Biology. ASM Press; 1996
A142: 138 | B142: Pittard A.J.: Biosynthesis of the Aromatic Amino Acids. In Escherichia coli and Salmonella Cellular and Molecular Biology. ASM Press; 1996
... A145: 141 | B145: W. Boos and J.M. Lucht: Periplasmic binding protein-dependent ABC transporters. In Escherichia coli and Salmonella Cellular and Molecular Biology. ASM Press; 1996
A147: Websites
A148: 142 | B148: TC-DB Release 1.2 [ http://tcdb.ucsd.edu/tcdb/background.php]

Sheet Transmembrane_reactions_reed
A1: Abbreviation | B1: OfficialName | C1: Equation (note [c] and [e] at the beginning refer to the compartment the reaction takes place in, cytosolic and extracellular respectively) | F1: Subsystem | G1: ProteinClassDescription | H1: Ref. (listed below)
A2: 12PPDt | B2: S-Propane-1,2-diol facilitated transport | C2: 12ppd-S[e] <=> 12ppd-S[c] | D2: -300 | E2: 300 | F2: Transport, Extracellular | H2: 125
A3: ABUTt2 | B3: 4-aminobutyrate transport in via proton symport | C3: 4abut[e] + h[e] <=> 4abut[c] + h[c] | D3: -300 | E3: 300 | F3: Transport, Extracellular
A4: ACACt2 | B4: acetoacetate transport via proton symport | C4: acac[e] + h[e] <=> acac[c] + h[c] | D4: -300 | E4: 300 | F4: Putative Transporters
A5: ACALDt | B5: acetaldehyde reversible transport | C5: acald[e] <=> acald[c] | D5: -300 | E5: 300 | F5: Transport, Extracellular
A6: ACGApts | B6: N-Acetyl-D-glucosamine transport via PEP:Pyr PTS | C6: acgam[e] + pep[c] <=> acgam6p[c] + pyr[c] | D6: -300 | E6: 300 | F6: Transport, Extracellular | H6: 132
A7: ACMANApts | B7: N-acetyl-D-mannosamine transport via PTS | C7: acmana[e] + pep[c] <=> acmanap[c] + pyr[c] | D7: -300 | E7: 300 | F7: Transport, Extracellular | H7: 84
A8: ACNAMt2 | B8: N-acetylneuraminate proton symport | C8: acnam[e] + h[e] <=> acnam[c] + h[c] | D8: -300 | E8: 300 | F8: Transport, Extracellular
A9: ACt2r | B9: acetate reversible transport via proton symport | C9: ac[e] + h[e] <=> ac[c] + h[c] | D9: -300 | E9: 300 | F9: Transport, Extracellular
A10: ADEt2r | B10: adenine transport via proton symport (reversible) | C10: ade[e] + h[e] <=> ade[c] + h[c] | D10: -300 | E10: 300 | F10: Transport, Extracellular
A11: ADNt2 | B11: adenosine transport in via proton symport | C11: adn[e] + h[e] <=> adn[c] + h[c] | D11: -300 | E11: 300 | F11: Transport, Extracellular
A12: ADNt2r | B12: adenosine transport in via proton symport, reversible | C12: adn[e] + h[e] <=> adn[c] + h[c] | D12: -300 | E12: 300 | F12: Transport, Extracellular | H12: 75
A13: AKGt2r | B13: 2-oxoglutarate reversible transport via symport | C13: akg[e] + h[e] <=> akg[c] + h[c] | D13: -300 | E13: 300 | F13: Transport, Extracellular
A14: ALAabc | B14: L-alanine transport via ABC system | C14: ala-L[e] + atp[c] + h2o[c] <=> adp[c] + ala-L[c] + h[c] + pi[c] | D14: -300 | E14: 300 | F14: Transport, Extracellular | H14: 93
A15: ALARi | B15: alanine racemase (irreversible) | C15: ala-L[c] <=> ala-D[c] | D15: -300 | E15: 300 | F15: Alanine and aspartate metabolism | G15: EC-5.1.1.1
A16: ALAt2r | B16: L-alanine reversible transport via proton symport | C16: ala-L[e] + h[e] <=> ala-L[c] + h[c] | D16: -300 | E16: 300 | F16: Putative Transporters | H16: 93
A17: ALLTNt2r | B17: allantoin transport in via proton symport | C17: alltn[e] + h[e] <=> alltn[c] + h[c] | D17: -300 | E17: 300 | F17: Putative Transporters
A18: ARBabc | B18: L-arabinose transport via ABC system | C18: arab-L[e] + atp[c] + h2o[c] <=> adp[c] + arab-L[c] + h[c] + pi[c] | D18: -300 | E18: 300 | F18: Transport, Extracellular
A19: ARBt2r | B19: L-arabinose transport via proton symport | C19: arab-L[e] + h[e] <=> arab-L[c] + h[c] | D19: -300 | E19: 300 | F19: Transport, Extracellular
A20: ARGabc | B20: L-arginine transport via ABC system | C20: arg-L[e] + atp[c] + h2o[c] <=> adp[c] + arg-L[c] + h[c] + pi[c] | D20: -300 | E20: 300 | F20: Transport, Extracellular
A21: ARGORNt7 | B21: arginine/ornithine antiporter | C21: arg-L[e] + orn[c] <=> arg-L[c] + orn[e] | D21: -300 | E21: 300 | F21: Putative Transporters
A22: ASNabc | B22: L-asparagine transport via ABC system | C22: asn-L[e] + atp[c] + h2o[c] <=> adp[c] + asn-L[c] + h[c] + pi[c] | D22: -300 | E22: 300 | F22: Transport, Extracellular
A23: ASNt2r | B23: L-asparagine reversible transport via proton symport | C23: asn-L[e] + h[e] <=> asn-L[c] + h[c] | D23: -300 | E23: 300 | F23: Transport, Extracellular
A24: ASPabc | B24: L-aspartate transport via ABC system | C24: asp-L[e] + atp[c] + h2o[c] <=> adp[c] + asp-L[c] + h[c] + pi[c] | D24: -300 | E24: 300 | F24: Transport, Extracellular
A25: ASPt2 | B25: L-aspartate transport in via proton symport | C25: asp-L[e] + h[e] <=> asp-L[c] + h[c] | D25: -300 | E25: 300 | F25: Transport, Extracellular
A26: ASPt22 | B26: Aspartate transport via proton symport (2 H) | C26: asp-L[e] + (2) h[e] <=> asp-L[c] + (2) h[c] | D26: -300 | E26: 300 | F26: Transport, Extracellular | H26: 53
A27: ASPt23 | B27: L-asparate transport via proton symport (3 H) | C27: asp-L[e] + (3) h[e] <=> asp-L[c] + (3) h[c] | D27: -300 | E27: 300 | F27: Transport, Extracellular | H27: 53
A28: ATPS4r | B28: ATP synthase (four protons for one ATP) | C28: adp[c] + (4) h[e] + pi[c] <=> atp[c] + (3) h[c] + h2o[c] | D28: -300 | E28: 300 | F28: Oxidative phosphorylation | G28: EC-3.6.3.14
A29: BUTt2r | B29: Butyrate transport via proton symport, reversible | C29: but[e] + h[e] <=> but[c] + h[c] | D29: -300 | E29: 300 | F29: Putative Transporters
A30: CADVt | B30: Lysine/Cadaverine antiporter | C30: 15dap[c] + h[e] + lys-L[e] <=> 15dap[e] + h[c] + lys-L[c] | D30: -300 | E30: 300 | F30: Transport, Extracellular
A31: CBL1abc | B31: Cob(1)alamin transport via ABC system | C31: atp[c] + cbl1[e] + h2o[c] <=> adp[c] + cbl1[c] + h[c] + pi[c] | D31: -300 | E31: 300 | F31: Transport, Extracellular | H31: 13141
A32: CHLabc | B32: choline transport via ABC system | C32: atp[c] + chol[e] + h2o[c] <=> adp[c] + chol[c] + h[c] + pi[c] | D32: -300 | E32: 300 | F32: Putative Transporters
A33: CHLt2r | B33: choline transport via proton symport, reversible | C33: chol[e] + h[e] <=> chol[c] + h[c] | D33: -300 | E33: 300 | F33: Transport, Extracellular | H33: 64
A34: CITt7 | B34: Citrate transport via succinate antiport | C34: cit[e] + succ[c] <=> cit[c] + succ[e] | D34: -300 | E34: 300 | F34: Transport, Extracellular | H34: 87
A35: CO2t | B35: CO2 transporter via diffusion | C35: co2tot[e] <=> co2tot[c] | D35: -300 | E35: 300 | F35: Transport, Extracellular
A36: CRNt7 | B36: Carnitine/butyrobetaine antiporter | C36: crn[e] + gbbtn[c] <=> crn[c] + gbbtn[e] | D36: -300 | E36: 300 | F36: Transport, Extracellular | H36: 54
A37: CSNt2 | B37: cytosine transport in via proton symport | C37: csn[e] + h[e] <=> csn[c] + h[c] | D37: -300 | E37: 300 | F37: Transport, Extracellular
A38: CYNTt2 | B38: Cyanate transport via proton symport | C38: cynt[e] + h[e] <=> cynt[c] + h[c] | D38: -300 | E38: 300 | F38: Putative Transporters | H38: 105142
A39: CYSabc | B39: L-cysteine transport via ABC system | C39: atp[c] + cys-L[e] + h2o[c] <=> adp[c] + cys-L[c] + h[c] + pi[c] | D39: -300 | E39: 300 | F39: Transport, Extracellular
A40: CYTBD | B40: cytochrome oxidase bd (ubiquinol-8: 2 protons) | C40: (2) h[c] + (0.5) o2[c] + q8h2[c] <=> (2) h[e] + h2o[c] + q8[c] | D40: -300 | E40: 300 | F40: Oxidative phosphorylation
...

Sheet Transmembrane reactions_Orth
A1: Abbreviation | B1: Lower Bound | C1: Upper Bound | D1: Stoichiometry | E1: Intracellular part | F1: Transmembrane part | G1: Transport map
A2: ADNt2 | B2: -300 | C2: 300 | D2: adn[e] <=> adn[c] | K2: ALARi
A3: ASPt2 | B3: -300 | C3: 300 | D3: asp-L[e] <=> asp-L[c] | K3: FUMt23 | L3: Fumarate transport via proton symport (3 H) | M3: Transport, Extracellular | N3: fum[e] + (3) h[e] <=> fum[c] + (3) h[c]
A4: CYTBD | B4: -300 | C4: 300 | D4: (0.5) o2[c] + q8h2[c] <=> h2o[c] + q8[c] | K4: GALUi | L4: UTP-glucose-1-phosphate uridylyltransferase (irreversible) | M4: Cell Envelope Biosynthesis | N4: g1p[c] + h[c] + utp[c] <=> ppi[c] + udpg[c]
A5: CYTDt2 | B5: -300 | C5: 300 | D5: cytd[e] <=> cytd[c] | K5: GLCDe | L5: Glucose dehydrogenase (ubiquinone-8 as acceptor) | M5: Oxidative phosphorylation | N5: glc-D[e] + h2o[e] + q8[c] <=> glcn[e] + h[e] + q8h2[c]
A6: FUMt22 | B6: -300 | C6: 300 | D6: fum[e] <=> fum[c] | K6: INSt2r | L6: inosine transport in via proton symport, reversible | M6: Transport, Extracellular | N6: h[e] + ins[e] <=> h[c] + ins[c]
A7: GUAt | B7: -300 | C7: 300 | D7: gua[e] <=> gua[c] | K7: LCADi | L7: lactaldehyde dehydrogenase | M7: Alternate Carbon Metabolism | N7: h2o[c] + lald-L[c] + nad[c] <=> (2) h[c] + lac-L[c] + nadh[c]
A8: INSt2 | B8: -300 | C8: 300 | D8: ins[e] <=> ins[c] | K8: MALt23 | L8: Malate transport via proton symport (3 H) | M8: Transport, Extracellular | N8: (3) h[e] + mal-L[e] <=> (3) h[c] + mal-L[c]
A9: MALt22 | B9: -300 | C9: 300 | D9: mal-L[e] <=> mal-L[c] | K9: NAt32 | L9: sodium proton antiporter (H:NA is 2) | M9: Transport, Extracellular | N9: (2) h[e] + na1[c] <=> (2) h[c] + na1[e]
A10: NAt31 | B10: -300 | C10: 300 | D10: na1[c] <=> na1[e] | K10: SUCCt23 | L10: Succintate transport via proton symport (3 H) | M10: Transport, Extracellular | N10: (3) h[e] + succ[e] <=> (3) h[c] + succ[c]
A11: SUCCt22 | B11: -300 | C11: 300 | D11: succ[e] <=> succ[c] | K11: THMDt2r | L11: thymidine transport in via proton symport, reversible | M11: Transport, Extracellular | N11: h[e] + thymd[e] <=> h[c] + thymd[c]
A12: THMDt2 | B12: -300 | C12: 300 | D12: thymd[e] <=> thymd[c] | K12: URAt2r | L12: uracil transport in via proton symport, reversible | M12: Putative Transporters | N12: h[e] + ura[e] <=> h[c] + ura[c]
A13: URAt2 | B13: -300 | C13: 300 | D13: ura[e] <=> ura[c] | K13: URIt2r | L13: uridine transport in via proton symport, reversible | M13: Transport, Extracellular | N13: h[e] + uri[e] <=> h[c] + uri[c]
A14: URIt2 | B14: -300 | C14: 300 | D14: uri[e] <=> uri[c] | K14: XANt2 | L14: xanthine transport in via proton symport | M14: Putative Transporters | N14: h[e] + xan[e] <=> h[c] + xan[c]
A15: XANt | B15: -300 | C15: 300 | D15: xan[e] <=> xan[c]
A16: 12PPDt | B16: -300 | C16: 300 | D16: 12ppd-S[e] <=> 12ppd-S[c]
A17: ABUTt2 | B17: -300 | C17: 300 | D17: 4abut[e] <=> 4abut[c]
A18: ACACt2 | B18: -300 | C18: 300 | D18: acac[e] <=> acac[c]
A19: ACALDt | B19: -300 | C19: 300 | D19: acald[e] <=> acald[c]
A20: ACGApts | B20: -300 | C20: 300 | D20: pep[c] + acgam[e] <=> acgam6p[c] + pyr[c]
A21: ACMANApts | B21: -300 | C21: 300 | D21: pep[c] + acmana[e] <=> acmanap[c] + pyr[c]
A22: ACNAMt2 | B22: -300 | C22: 300 | D22: acnam[e] <=> acnam[c]
A23: ACt2r | B23: -300 | C23: 300 | D23: ac[e] <=> ac[c]
A24: ADEt2r | B24: -300 | C24: 300 | D24: ade[e] <=> ade[c]
A25: AKGt2r | B25: -300 | C25: 300 | D25: akg[e] <=> akg[c]
A26: ALAabc | B26: -300 | C26: 300 | D26: atp[c] + h2o[c] + ala-L[e] <=> adp[c] + ala-L[c] + pi[c]
... A189: XYLt2 | B189: -300 | C189: 300 | D189: xyl-D[e] <=> xyl-D[c]

Sheet Transmembrane reactions old
A1: Abbreviation | B1: Lower Bound | C1: Upper Bound | D1: Stoichiometry | E1: Intracellular part | F1: Transmembrane part | G1: Transport map | I1: chargetransport | J1: type | L1: reed name | M1: OfficialName
A2: ABUTt2_0 | B2: 0 | C2: 300 | D2: 4abut[e] <=> 4abut[c] | F2: 4abut{0}[e] <=> 4abut{0}[c] | G2: c|>|e | H2: eq | I2: 0 | J2: one metabolite transport | L2: ABUTt2 | M2: 4-aminobutyrate transport in via proton symport
A3: ACACt2_-1 | B3: -300 | C3: 300 | D3: acac[e] <=> acac[c] | F3: acac{-1}[e] <=> acac{-1}[c] | G3: c|>|e | I3: 0 | J3: one metabolite transport | L3: ACACt2 | M3: acetoacetate transport via proton symport
A4: ACACt2_-1+1H | B4: -300 | C4: 300 | D4: acac[e] <=> acac[c] | F4: acac{-1}[e] + h{1}[e] <=> acac{-1}[c] + h{1}[c] | G4: c|>|e | H4: eq | I4: 0 | J4: one metabolite transport
A5: ACNAMt2_-1 | B5: -300 | C5: 300 | D5: acnam[e] <=> acnam[c] | F5: acnam{-1}[e] <=> acnam{-1}[c] | G5: c|>|e | I5: 0 | J5: one metabolite transport | L5: ACNAMt2 | M5: N-acetylneuraminate proton symport | N5: Transport, Extracellular
A6: ACNAMt2_-1+1H | B6: -300 | C6: 300 | D6: acnam[e] <=> acnam[c] | F6: acnam{-1}[e] + h{1}[e] <=> acnam{-1}[c] + h{1}[c] | G6: c|>|e | H6: eq | I6: 0 | J6: one metabolite transport
A7: ACt2r_-1 | B7: -300 | C7: 300 | D7: ac[e] <=> ac[c] | F7: ac{-1}[e] <=> ac{-1}[c] | G7: c|>|e | I7: 0 | J7: one metabolite transport | L7: ACt2r | M7: acetate reversible transport via proton symport
A8: ACt2r_-1+1H | B8: -300 | C8: 300 | D8: ac[e] <=> ac[c] | F8: ac{-1}[e] + h{1}[e] <=> ac{-1}[c] + h{1}[c] | G8: c|>|e | H8: eq | I8: 0 | J8: one metabolite transport
A9: AKGt2r_-2 | B9: -300 | C9: 300 | D9: akg[e] <=> akg[c] | F9: akg{-2}[e] <=> akg{-2}[c] | G9: c|>|e | I9: -1 | J9: one metabolite transport | L9: AKGt2r | M9: 2-oxoglutarate reversible transport via symport
A10: AKGt2r_-2+2H | B10: -300 | C10: 300 | D10: akg[e] <=> akg[c] | F10: akg{-2}[e] + (2) h{1}[e] <=> akg{-2}[c] + (2) h{1}[c] | G10: c|>|e | H10: eq | I10: 0 | J10: symport
A11: ALAabc_0 | B11: 0 | C11: 300 | D11: ala-L[e] + atp[c] + h2o[c] <=> adp[c] + ala-L[c] + pi[c] | E11: atp[c] + h2o[c] <=> adp[c] + pi[c] | F11: ala-L{0}[e] <=> ala-L{0}[c] | G11: c|>|e | I11: 0 | J11: one metabolite transport | L11: ALAabc | M11: L-alanine transport via ABC system
A12: ALAt2r_0 | B12: -300 | C12: 300 | D12: ala-L[e] <=> ala-L[c] | F12: ala-L{0}[e] <=> ala-L{0}[c] | G12: c|>|e | H12: eq | I12: 0 | J12: one metabolite transport | L12: ALAt2r | M12: L-alanine reversible transport via proton symport
A13: ARBabc_0 | B13: 0 | C13: 300 | D13: arab-L[e] + atp[c] + h2o[c] <=> adp[c] + arab-L[c] + pi[c] | E13: atp[c] + h2o[c] <=> adp[c] + pi[c] | F13: arab-L{0}[e] <=> arab-L{0}[c] | G13: c|>|e | I13: 0 | J13: one metabolite transport | L13: ARBabc | M13: L-arabinose transport via ABC system
A14: ARBt2r_0 | B14: -300 | C14: 300 | D14: arab-L[e] <=> arab-L[c] | F14: arab-L{0}[e] <=> arab-L{0}[c] | G14: c|>|e | H14: eq | I14: 0 | J14: one metabolite transport | L14: ARBt2r | M14: L-arabinose transport via proton symport
A15: ARGabc_1 | B15: 0 | C15: 300 | D15: arg-L[e] + atp[c] + h2o[c] <=> adp[c] + arg-L[c] + pi[c] | E15: atp[c] + h2o[c] <=> adp[c] + pi[c] | F15: arg-L{1}[e] <=> arg-L{1}[c] | G15: c|>|e | I15: 0 | J15: one metabolite transport | L15: ARGabc | M15: L-arginine transport via ABC system
A16: ARGORNt7_1_1 | B16: -300 | C16: 300 | D16: arg-L[e] + orn[c] <=> arg-L[c] + orn[e] | F16: arg-L{1}[e] + orn{1}[c] <=> arg-L{1}[c] + orn{1}[e] | G16: c|>|e | H16: eq | I16: 0 | J16: one metabolite transport | L16: ARGORNt7 | M16: arginine/ornithine antiporter
A17: ASNabc_0 | B17: 0 | C17: 300 | D17: asn-L[e] + atp[c] + h2o[c] <=> adp[c] + asn-L[c] + pi[c] | E17: atp[c] + h2o[c] <=> adp[c] + pi[c] | F17: asn-L{0}[e] <=> asn-L{0}[c] | G17: c|>|e | I17: 0 | J17: one metabolite transport | L17: ASNabc | M17: L-asparagine transport via ABC system
A18: ASNt2r_0 | B18: -300 | C18: 300 | D18: asn-L[e] <=> asn-L[c] | F18: asn-L{0}[e] <=> asn-L{0}[c] | G18: c|>|e | H18: eq | I18: 0 | J18: one metabolite transport | L18: ASNt2r | M18: L-asparagine reversible transport via proton symport
A19: ASPabc_-1 | B19: 0 | C19: 300 | D19: asp-L[e] + atp[c] + h2o[c] <=> adp[c] + asp-L[c] + pi[c] | E19: atp[c] + h2o[c] <=> adp[c] + pi[c] | F19: asp-L{-1}[e] <=> asp-L{-1}[c] | G19: c|>|e | I19: 0 | J19: one metabolite transport | L19: ASPabc | M19: L-aspartate transport via ABC system
A20: ASPt2_-1 | B20: 0 | C20: 300 | D20: asp-L[e] <=> asp-L[c] | F20: asp-L{-1}[e] <=> asp-L{-1}[c] | G20: c|>|e | I20: 0 | J20: one metabolite transport | L20: ASPt2 | M20: L-aspartate transport in via proton symport
A21: ASPt2_-1+1H | B21: 0 | C21: 300 | D21: asp-L[e] <=> asp-L[c] | F21: asp-L{-1}[e] + h{1}[e] <=> asp-L{-1}[c] + h{1}[c] | G21: c|>|e | H21: eq | I21: 2 | J21: one metabolite transport
A22: ATPS4rpp_4 | B22: -300 | C22: 300 | D22: adp[c] + pi[c] <=> atp[c] + h2o[c] | E22: adp[c] + pi[c] <=> atp[c] + h2o[c] | F22: (4) h{1}[e] <=> (4) h{1}[c] | G22: c|>|e | I22: 0 | J22: one metabolite transport | L22: ATPS4r | M22: ATP synthase (four protons for one ATP)
A23: BUTt2r_-1 | B23: -300 | C23: 300 | D23: but[e] <=> but[c] | F23: but{-1}[e] <=> but{-1}[c] | G23: c|>|e | I23: 0 | J23: one metabolite transport | L23: BUTt2r | M23: Butyrate transport via proton symport, reversible
A24: BUTt2r_-1+1H | B24: -300 | C24: 300 | D24: but[e] <=> but[c] | F24: but{-1}[e] + h{1}[e] <=> but{-1}[c] + h{1}[c] | G24: c|>|e | H24: eq | I24: 0 | J24: one metabolite transport
A25: CADVt_-1+1H | B25: 0 | C25: 300 | D25: 15dap[c] + lys-L[e] <=> 15dap[e] + lys-L[c] | F25: 15dap{2}[c] + h{1}[e] + lys-L{1}[e] <=> 15dap{2}[e] + h{1}[c] + lys-L{1}[c] | G25: c|>|e | H25: eq | I25: 0 | J25: one metabolite transport | L25: CADVt | M25: Lysine/Cadaverine antiporter
A26: CADVt_2_1 | B26: 0 | C26: 300 | D26: 15dap[c] + lys-L[e] <=> 15dap[e] + lys-L[c] | F26: 15dap{2}[c] + lys-L{1}[e] <=> 15dap{2}[e] + lys-L{1}[c] | G26: c|>|e | I26: 0 | J26: one metabolite transport
A27: Cex | B27: -300 | C27: 300 | F27: charge{1}[c] <=> charge{1}[e] | G27: c|>|e
A28: CHLabc_1 | B28: 0 | C28: 300 | D28: atp[c] + chol[e] + h2o[c] <=> adp[c] + chol[c] + pi[c] | E28: atp[c] + h2o[c] <=> adp[c] + pi[c] | F28: chol{1}[e] <=> chol{1}[c] | G28: c|>|e | I28: 0 | J28: one metabolite transport | L28: CHLabc | M28: choline transport via ABC system
A29: CHLt2r_1 | B29: -300 | C29: 300 | D29: chol[e] <=> chol[c] | F29: chol{1}[e] <=> chol{1}[c] | G29: c|>|e | I29: 0 | J29: one metabolite transport | L29: CHLt2r | M29: choline transport via proton symport, reversible
A30: CHLt2r_1+1H | B30: -300 | C30: 300 | D30: chol[e] <=> chol[c] | F30: chol{1}[e] + h{1}[c] <=> chol{1}[c] + h{1}[e] | G30: c|>|e | H30: eq | I30: 0 | J30: one metabolite transport
A31: CITt7_1+1H | B31: 0 | C31: 300 | D31: cit[e] + succ[c] <=> cit[c] + succ[e] | F31: cit{-3}[e] + h{1}[e] + succ{-2}[c] <=> cit{-3}[c] + h{1}[c] + succ{-2}[e] | G31: c|>|e | H31: eq | I31: 0 | J31: one metabolite transport | L31: CITt7 | M31: Citrate transport via succinate antiport
A32: CITt7_-2_-3 | B32: -300 | C32: 300 | D32: cit[e] + succ[c] <=> cit[c] + succ[e] | F32: cit{-3}[e] + succ{-2}[c] <=> cit{-3}[c] + succ{-2}[e] | G32: c|>|e | I32: 0 | J32: one metabolite transport
A33: CO2t_0 | B33: -300 | C33: 300 | D33: co2tot[e] <=> co2tot[c] | F33: co2tot{0}[e] <=> co2tot{0}[c] | G33: c|>|e | H33: eq | I33: 0 | J33: one metabolite transport | L33: CO2t | M33: CO2 transporter via diffusion
A34: CSNt2_0 | B34: 0 | C34: 300 | D34: csn[e] <=> csn[c] | F34: csn{0}[e] <=> csn{0}[c] | G34: c|>|e | H34: eq | I34: 0 | J34: one metabolite transport | L34: CSNt2 | M34: cytosine transport in via proton symport
A35: CSNt2_-1 | B35: 0 | C35: 300 | D35: csn[e] <=> csn[c] | F35: csn{-1}[e] <=> csn{-1}[c] | G35: c|>|e | I35: 0 | J35: one metabolite transport
A36: CYNTt2_-1 | B36: 0 | C36: 300 | D36: cynt[e] <=> cynt[c] | F36: cynt{-1}[e] <=> cynt{-1}[c] | G36: c|>|e | I36: 0 | J36: one metabolite transport | L36: CYNTt2 | M36: Cyanate transport via proton symport
A37: CYNTt2_-1+1H | B37: 0 | C37: 300 | D37: cynt[e] <=> cynt[c] | F37: cynt{-1}[e] + h{1}[e] <=> cynt{-1}[c] + h{1}[c] | G37: c|>|e | H37: eq | I37: 0 | J37: one metabolite transport
A38: CYTBDpp_1 | B38: 0 | C38: 300 | D38: (0.5) o2[c] + q8h2[c] <=> h2o[c] + q8[c] | E38: (0.5) o2[c] + q8h2[c] <=> h2o[c] + q8[c] | F38: (2) h{1}[c] <=> (2) h{1}[e] | G38: c|>|e | I38: 0 | J38: one metabolite transport | L38: CYTBD | M38: cytochrome oxidase bd (ubiquinol-8: 2 protons)
A39: CYTBO34pp_4 | B39: 0 | C39: 300 | D39: (0.5) o2[c] + q8h2[c] <=> h2o[c] + q8[c] | E39: (0.5) o2[c] + q8h2[c] <=> h2o[c] + q8[c] | F39: (4) h{1}[c] <=> (4) h{1}[e] | G39: c|>|e | I39: 0 | J39: one metabolite transport | L39: CYTBO3 | M39: cytochrome oxidase bo3 (ubiquinol-8: 2.5 protons)
A40: DDGLCNt2r_-1 | B40: -300 | C40: 300 | D40: 2ddglcn[e] <=> 2ddglcn[c] | F40: 2ddglcn{-1}[e] <=> 2ddglcn{-1}[c] | G40: c|>|e | I40: 0 | J40: one metabolite transport | L40: DDGLCNt2r | M40: 2-dehydro-3-deoxy-D-gluconate transport via proton symport, reversible
...

Sheet Sheet3
A1: Abbreviation | B1: Lower Bound | C1: Upper Bound | D1: Stoichiometry | E1: Intracellular part | F1: Transmembrane part | G1: Transport map | I1: OfficialName | J1: reed Formula | K1: Subsystem | L1: EC Number | M1: ref
A2: 12PPDt | B2: -300 | C2: 300 | D2: 12ppd-S[e] <=> 12ppd-S[c] | F2: 12ppd-S{0}[e] <=> 12ppd-S{0}[c] | G2: c|>|e | I2: S-Propane-1,2-diol facilitated transport | J2: 12ppd-S[e] <=> 12ppd-S[c] | K2: Transport, Extracellular | M2: 125
A3: ABUTt2 | B3: -300 | C3: 300 | D3: 4abut[e] <=> 4abut[c] | F3: 4abut{0}[e] <=> 4abut{0}[c] | G3: c|>|e | I3: 4-aminobutyrate transport in via proton symport | J3: 4abut[e] + h[e] <=> 4abut[c] + h[c] | K3: Transport, Extracellular
A4: ACACt2 | B4: -300 | C4: 300 | D4: acac[e] <=> acac[c] | F4: acac{-1}[e] + h{1}[e] <=> acac{-1}[c] + h{1}[c] | G4: c|>|e | I4: acetoacetate transport via proton symport | J4: acac[e] + h[e] <=> acac[c] + h[c] | K4: Putative Transporters
A5: ACALDt | B5: -300 | C5: 300 | D5: acald[e] <=> acald[c] | F5: acald{0}[e] <=> acald{0}[c] | G5: c|>|e | I5: acetaldehyde reversible transport | J5: acald[e] <=> acald[c] | K5: Transport, Extracellular
A6: ACGApts | B6: -300 | C6: 300 | D6: acgam[e] + pep[c] <=> acgam6p[c] + pyr[c] | E6: acgam[c] + pep[c] <=> acgam6p[c] + pyr[c] | F6: acgam{0}[e] <=> acgam{0}[c] | G6: c|>|e | I6: N-Acetyl-D-glucosamine transport via PEP:Pyr PTS | J6: acgam[e] + pep[c] <=> acgam6p[c] + pyr[c] | K6: Transport, Extracellular | M6: 132
A7: ACMANApts | B7: -300 | C7: 300 | D7: acmana[e] + pep[c] <=> acmanap[c] + pyr[c] | E7: acmana[c] + pep[c] <=> acmanap[c] + pyr[c] | F7: acmana{0}[e] <=> acmana{0}[c] | G7: c|>|e | I7: N-acetyl-D-mannosamine transport via PTS | J7: acmana[e] + pep[c] <=> acmanap[c] + pyr[c] | K7: Transport, Extracellular | M7: 84
A8: ACNAMt2 | B8: -300 | C8: 300 | D8: acnam[e] <=> acnam[c] | F8: acnam{-1}[e] + h{1}[e] <=> acnam{-1}[c] + h{1}[c] | G8: c|>|e | I8: N-acetylneuraminate proton symport | J8: acnam[e] + h[e] <=> acnam[c] + h[c] | K8: Transport, Extracellular
A9: ACt2r | B9: -300 | C9: 300 | D9: ac[e] <=> ac[c] | F9: ac{-1}[e] + h{1}[e] <=> ac{-1}[c] + h{1}[c] | G9: c|>|e | I9: acetate reversible transport via proton symport | J9: ac[e] + h[e] <=> ac[c] + h[c] | K9: Transport, Extracellular
A10: ADEt2r | B10: -300 | C10: 300 | D10: ade[e] <=> ade[c] | F10: ade{0}[e] <=> ade{0}[c] | G10: c|>|e | I10: adenine transport via proton symport (reversible) | J10: ade[e] + h[e] <=> ade[c] + h[c] | K10: Transport, Extracellular
A11: ADNt2 | B11: -300 | C11: 300 | D11: adn[e] <=> adn[c] | F11: adn{0}[e] <=> adn{0}[c] | G11: c|>|e | I11: adenosine transport in via proton symport | J11: adn[e] + h[e] <=> adn[c] + h[c] | K11: Transport, Extracellular
A12: AKGt2r | B12: -300 | C12: 300 | D12: akg[e] <=> akg[c] | F12: akg{-2}[e] + (2) h{1}[e] <=> akg{-2}[c] + (2) h{1}[c] | G12: c|>|e | I12: 2-oxoglutarate reversible transport via symport | J12: akg[e] + h[e] <=> akg[c] + h[c] | K12: Transport, Extracellular
A13: ALAabc | B13: -300 | C13: 300 | D13: ala-L[e] + (2) atp[c] + h2o[c] <=> (2) adp[c] + ala-L[c] + (2) pi[c] | E13: (2) atp[c] + (2) h2o[c] <=> (2) adp[c] + (2) pi[c] | F13: ala-L{0}[e] <=> ala-L{0}[c] | G13: c|>|e | I13: L-alanine transport via ABC system | J13: ala-L[e] + atp[c] + h2o[c] <=> adp[c] + ala-L[c] + h[c] + pi[c] | K13: Transport, Extracellular | M13: 93
A14: ALARi | B14: -300 | C14: 300 | D14: ala-L[e] <=> ala-L[c] | F14: ala-L{0}[e] <=> ala-L{0}[c] | G14: c|>|e | I14: alanine racemase (irreversible) | J14: ala-L[c] <=> ala-D[c] | K14: Alanine and aspartate metabolism | L14: EC-5.1.1.1
A15: ALAt2r | B15: -300 | C15: 300 | G15: c|>|e | I15: L-alanine reversible transport via proton symport | J15: ala-L[e] + h[e] <=> ala-L[c] + h[c] | K15: Putative Transporters | M15: 93
A16: ALLTNt2r | B16: -300 | C16: 300 | D16: alltn[e] <=> alltn[c] | F16: alltn{0}[e] <=> alltn{0}[c] | G16: c|>|e | I16: allantoin transport in via proton symport | J16: alltn[e] + h[e] <=> alltn[c] + h[c] | K16: Putative Transporters
